Workbook

Sheet Construct_Item_Map
A1: Variable name | B1: Construct | C1: Facet | D1: Survey item | E1: Response scale | F1: Reverse-coded | G1: Include in final survey | H1: Notes
A2: ovl_01 | B2: Overall | C2: Overall | D2: Overall, I have a positive experience working at this organization. | E2: agreement_5 | F2: No | G2: Yes
A3: eng_01 | B3: Engagement | C3: Motivation | D3: I feel motivated to do my best work. | E3: agreement_5 | F3: No | G3: Yes
A4: eng_02 | B4: Engagement | C4: Energy | D4: I feel energized by the work I do. | E4: agreement_5 | F4: No | G4: Yes
A5: eng_03 | B5: Engagement | C5: Accomplishment | D5: My work gives me a sense of accomplishment. | E5: agreement_5 | F5: No | G5: Yes
A6: eng_04 | B6: Engagement | C6: Advocacy | D6: I would recommend this organization as a good place to work. | E6: agreement_5 | F6: No | G6: Yes | H6: Review possible overlap with organizational commitment or belonging.
A7: mgr_01 | B7: Manager effectiveness | C7: Expectations | D7: My manager communicates expectations clearly. | E7: agreement_5 | F7: No | G7: Yes
A8: mgr_02 | B8: Manager effectiveness | C8: Feedback | D8: My manager provides feedback that helps me improve. | E8: agreement_5 | F8: No | G8: Yes
A9: mgr_03 | B9: Manager effectiveness | C9: Support | D9: My manager supports me when I encounter challenges. | E9: agreement_5 | F9: No | G9: Yes
A10: mgr_04 | B10: Manager effectiveness | C10: Fairness | D10: My manager treats team members fairly. | E10: agreement_5 | F10: No | G10: Yes
A11: psy_01 | B11: Psychological safety | C11: Speaking up | D11: I can raise concerns on my team without fear of negative consequences. | E11: agreement_5 | F11: No | G11: Yes
A12: psy_02 | B12: Psychological safety | C12: Admitting mistakes | D12: People on my team can acknowledge mistakes openly. | E12: agreement_5 | F12: No | G12: Yes
A13: psy_03 | B13: Psychological safety | C13: Asking for help | D13: I feel comfortable asking members of my team for help. | E13: agreement_5 | F13: No | G13: Yes
A14: psy_04 | B14: Psychological safety | C14: Sharing different views | D14: Different perspectives are welcomed on my team. | E14: agreement_5 | F14: No | G14: Yes
A15: grwth_01 | B15: Growth and development | C15: Skill development | D15: I have opportunities to develop skills that are relevant to my work. | E15: agreement_5 | F15: No | G15: Yes
A16: grwth_02 | B16: Growth and development | C16: Career clarity | D16: I understand the career opportunities available to me at this organization. | E16: agreement_5 | F16: No | G16: Yes | H16: Compare with grwth_04 for possible redundancy.
A17: grwth_03 | B17: Growth and development | C17: Development support | D17: I receive support for my professional development. | E17: agreement_5 | F17: No | G17: Yes
A18: grwth_04 | B18: Growth and development | C18: Future opportunities | D18: I can see opportunities for my continued growth at this organization. | E18: agreement_5 | F18: No | G18: Yes
A19: wrk_01 | B19: Workload sustainability | C19: Manageability | D19: My workload is manageable. | E19: agreement_5 | F19: No | G19: Yes
A20: wrk_02 | B20: Workload sustainability | C20: Time | D20: I have enough time to complete my work effectively. | E20: agreement_5 | F20: No | G20: Yes
A21: wrk_03 | B21: Workload sustainability | C21: Staffing/resources | D21: I have access to the resources needed to meet my work responsibilities. | E21: agreement_5 | F21: No | G21: Yes | H21: Review whether this loads with workload or a broader enablement/resources factor.
A22: wrk_04 | B22: Workload sustainability | C22: Sustainable pace | D22: I can maintain my current work pace without becoming overwhelmed. | E22: agreement_5 | F22: No | G22: Yes
A23: blg_01 | B23: Belonging | C23: Inclusion | D23: I feel included at this organization. | E23: agreement_5 | F23: No | G23: Yes
A24: blg_02 | B24: Belonging | C24: Respect | D24: I feel respected by the people I work with. | E24: agreement_5 | F24: No | G24: Yes
A25: blg_03 | B25: Belonging | C25: Authenticity | D25: I feel comfortable being myself at work. | E25: agreement_5 | F25: No | G25: Yes
A26: blg_04 | B26: Belonging | C26: Connection | D26: I feel connected to the people in this organization. | E26: agreement_5 | F26: No | G26: Yes
A27: its_01 | B27: Intent to stay | C27: Expected continued employment | D27: I expect to still be working at this organization one year from now. | E27: agreement_5 | F27: No | G27: Yes | H27: Timeframe intentionally fixed at one year
A28: its_02 | B28: Intent to stay | C28: Preference to remain | D28: I would prefer to continue working at this organization rather than seek employment elsewhere. | E28: agreement_5 | F28: No | G28: Yes
A29: comment_01 | B29: Open-ended | C29: Open-ended | D29: What is one thing this organization could do to improve your experience at work? | E29: open_text | F29: N/A | G29: Yes
A30: Total | G30: =SUBTOTAL(103,Table1[Include in final survey]) -> 28

Sheet Data_Dictionary
A1: Variable name | B1: Table | C1: Display label | D1: Description | E1: Data type | F1: Allowed values | G1: Missing-value rule | H1: Source | I1: Public reporting status | J1: Notes | K1: Variable group
A2: =Construct_Item_Map!$A2 -> ovl_01 | B2: survey_responses | C2: =Table1[[#This Row],[Facet]] -> Overall | D2: =Table1[[#This Row],[Survey item]] -> Overall, I have a positive experience working at this organization. | E2: Integer | F2: 1, 2, 3, 4, 5 | G2: Blank or NA when unanswered | H2: Survey response | I2: Aggregated only | J2: Optional overall benchmark; not included automatically in a scale
A3: =Construct_Item_Map!$A3 -> eng_01 | B3: survey_responses | C3: =Table1[[#This Row],[Facet]] -> Motivation | D3: =Table1[[#This Row],[Survey item]] -> I feel motivated to do my best work. | E3: Integer | F3: 1, 2, 3, 4, 5 | G3: Blank or NA when unanswered | H3: Survey response | I3: Aggregated only | J3: Not reverse-coded
A4: =Construct_Item_Map!$A4 -> eng_02 | B4: survey_responses | C4: =Table1[[#This Row],[Facet]] -> Energy | D4: =Table1[[#This Row],[Survey item]] -> I feel energized by the work I do. | E4: Integer | F4: 1, 2, 3, 4, 5 | G4: Blank or NA when unanswered | H4: Survey response | I4: Aggregated only | J4: Not reverse-coded
A5: =Construct_Item_Map!$A5 -> eng_03 | B5: survey_responses | C5: =Table1[[#This Row],[Facet]] -> Accomplishment | D5: =Table1[[#This Row],[Survey item]] -> My work gives me a sense of accomplishment. | E5: Integer | F5: 1, 2, 3, 4, 5 | G5: Blank or NA when unanswered | H5: Survey response | I5: Aggregated only | J5: Not reverse-coded
A6: =Construct_Item_Map!$A6 -> eng_04 | B6: survey_responses | C6: =Table1[[#This Row],[Facet]] -> Advocacy | D6: =Table1[[#This Row],[Survey item]] -> I would recommend this organization as a good place to work. | E6: Integer | F6: 1, 2, 3, 4, 5 | G6: Blank or NA when unanswered | H6: Survey response | I6: Aggregated only | J6: Not reverse-coded
A7: =Construct_Item_Map!$A7 -> mgr_01 | B7: survey_responses | C7: =Table1[[#This Row],[Facet]] -> Expectations | D7: =Table1[[#This Row],[Survey item]] -> My manager communicates expectations clearly. | E7: Integer | F7: 1, 2, 3, 4, 5 | G7: Blank or NA when unanswered | H7: Survey response | I7: Aggregated only | J7: Not reverse-coded
A8: =Construct_Item_Map!$A8 -> mgr_02 | B8: survey_responses | C8: =Table1[[#This Row],[Facet]] -> Feedback | D8: =Table1[[#This Row],[Survey item]] -> My manager provides feedback that helps me improve. | E8: Integer | F8: 1, 2, 3, 4, 5 | G8: Blank or NA when unanswered | H8: Survey response | I8: Aggregated only | J8: Not reverse-coded
A9: =Construct_Item_Map!$A9 -> mgr_03 | B9: survey_responses | C9: =Table1[[#This Row],[Facet]] -> Support | D9: =Table1[[#This Row],[Survey item]] -> My manager supports me when I encounter challenges. | E9: Integer | F9: 1, 2, 3, 4, 5 | G9: Blank or NA when unanswered | H9: Survey response | I9: Aggregated only | J9: Not reverse-coded
A10: =Construct_Item_Map!$A10 -> mgr_04 | B10: survey_responses | C10: =Table1[[#This Row],[Facet]] -> Fairness | D10: =Table1[[#This Row],[Survey item]] -> My manager treats team members fairly. | E10: Integer | F10: 1, 2, 3, 4, 5 | G10: Blank or NA when unanswered | H10: Survey response | I10: Aggregated only | J10: Not reverse-coded
A11: =Construct_Item_Map!$A11 -> psy_01 | B11: survey_responses | C11: =Table1[[#This Row],[Facet]] -> Speaking up | D11: =Table1[[#This Row],[Survey item]] -> I can raise concerns on my team without fear of negative consequences. | E11: Integer | F11: 1, 2, 3, 4, 5 | G11: Blank or NA when unanswered | H11: Survey response | I11: Aggregated only | J11: Not reverse-coded
A12: =Construct_Item_Map!$A12 -> psy_02 | B12: survey_responses | C12: =Table1[[#This Row],[Facet]] -> Admitting mistakes | D12: =Table1[[#This Row],[Survey item]] -> People on my team can acknowledge mistakes openly. | E12: Integer | F12: 1, 2, 3, 4, 5 | G12: Blank or NA when unanswered | H12: Survey response | I12: Aggregated only | J12: Not reverse-coded
A13: =Construct_Item_Map!$A13 -> psy_03 | B13: survey_responses | C13: =Table1[[#This Row],[Facet]] -> Asking for help | D13: =Table1[[#This Row],[Survey item]] -> I feel comfortable asking members of my team for help. | E13: Integer | F13: 1, 2, 3, 4, 5 | G13: Blank or NA when unanswered | H13: Survey response | I13: Aggregated only | J13: Not reverse-coded
... A29: =Construct_Item_Map!$A29 -> comment_01 | B29: survey_responses | C29: =Table1[[#This Row],[Facet]] -> Open-ended | D29: =Table1[[#This Row],[Survey item]] -> What is one thing this organization could do to improve your experience at work? | E29: Text | F29: Free-text response | G29: Blank or NA when unanswered | H29: Survey response | I29: Excluded from public row-level data | J29: Synthetic comments only; themes may be reported in aggregate
A30: employee_id | B30: employee_population | C30: Employee ID | D30: Synthetic identifier assigned to each employee. | E30: Text | F30: EMP0001–EMP3600 | G30: Never missing | H30: Generated | I30: Excluded | J30: Internal linkage field only | K30: Employee and survey identifiers
A31: survey_wave | B31: employee_population | C31: Survey wave | D31: Survey administration wave associated with the employee record. | E31: Text | F31: Wave 1, Wave 2 | G31: Never missing | H31: Generated | I31: Public | J31: One employee may appear in both waves | K31: Employee and survey identifiers
A32: survey_date | B32: employee_population | C32: Survey launch date | D32: Date on which the survey was launched. | E32: Date | F32: Valid date | G32: Never missing | H32: Generated | I32: Public | J32: Same date for all records within a wave | K32: Employee and survey identifiers
A33: business_unit | B33: employee_population | C33: Business unit | D33: Employee's assigned business unit at survey launch. | E33: Text | F33: Client Operations, Technology and Product, Corporate Services | G33: Never missing for eligible employees | H33: Generated | I33: Aggregated only | J33: Used for subgroup reporting | K33: Organizational variables
A34: department | B34: employee_population | C34: Department | D34: Employee's assigned department at survey launch. | E34: Text | F34: Customer Support, Implementation, Service Delivery, Engineering, Data and Analytics, Product, Human Resources, Finance, Sales and Marketing | G34: Never missing for eligible employees | H34: Generated | I34: Aggregated only | J34: Nested within business unit | K34: Organizational variables
A35: job_level | B35: employee_population | C35: Job level | D35: Employee's organizational job level at survey launch. | E35: Text | F35: Entry level, Professional, Senior Professional, Manager, Director and Above | G35: Never missing for eligible employees | H35: Generated | I35: Aggregated only | J35: Separate from manager status | K35: Organizational variables
A36: manager_status | B36: employee_population | C36: Manager status | D36: Indicates whether the employee directly manages other employees. | E36: Text | F36: Individual Contributor, People Manager | G36: Never missing for eligible employees | H36: Generated | I36: Aggregated only | J36: Do not infer solely from job level | K36: Organizational variables
A37: work_arrangement | B37: employee_population | C37: Work arrangement | D37: Employee's primary work arrangement at survey launch. | E37: Text | F37: On-site, Hybrid, Remote | G37: Never missing for eligible employees | H37: Generated | I37: Aggregated only | J37: May vary by department | K37: Organizational variables
A38: location_region | B38: employee_population | C38: Location region | D38: Broad geographic work location assigned to the employee. | E38: Text | F38: Northeast, South, Midwest, West | G38: Never missing for eligible employees | H38: Generated | I38: Aggregated only | J38: Use broad regions, not exact addresses | K38: Organizational variables
A39: hire_date | B39: employee_population | C39: Hire date | D39: Synthetic date on which the employee joined the organization. | E39: Date | F39: Valid date on or before survey date | G39: Never missing for eligible employees | H39: Generated | I39: Excluded | J39: Used to calculate tenure | K39: Tenure variables
A40: tenure_years | B40: employee_population | C40: Tenure in years | D40: Number of years between the hire date and survey launch date. | E40: Decimal | F40: 0 or greater | G40: Never missing when hire date is available | H40: Derived | I40: Aggregated only | J40: Calculated separately for each wave | K40: Tenure variables
A41: tenure_group | B41: employee_population | C41: Tenure group | D41: Grouped employee tenure at survey launch. | E41: Text | F41: Less than 1 year, 1–2 years, 3–5 years, 6–10 years, 11 or more years | G41: Never missing when tenure is available | H41: Derived | I41: Aggregated only | J41: Used for dashboard comparisons | K41: Tenure variables
... A48: response_status | B48: employee_population | C48: Response status | D48: Summarizes the employee's final survey participation status. | E48: Text | F48: Not eligible, Not invited, No response, Unusable response, Usable response | G48: Never missing | H48: Derived | I48: Aggregated only | J48: Derived from eligibility and response fields | K48: Eligibility and participation variables

Sheet Response_Scales
A1: Scale ID | B1: Value | C1: Response label | D1: Response category
A2: agreement_5 | B2: 1 | C2: Strongly disagree | D2: Unfavorable
A3: agreement_5 | B3: 2 | C3: Disagree | D3: Unfavorable
A4: agreement_5 | B4: 3 | C4: Neither agree nor disagree | D4: Neutral
A5: agreement_5 | B5: 4 | C5: Agree | D5: Favorable
A6: agreement_5 | B6: 5 | C6: Strongly agree | D6: Favorable

Sheet Population_Spec
A2: Survey Waves
A3: Parameter | B3: Wave 1 | C3: Wave 2
A4: Survey wave | B4: Wave 1 | C4: Wave 2
A5: Survey launch date | B5: 45945 | C5: 46127
A6: Approximate workforce size | B6: 3600 | C6: 3600
A7: Time between waves | B7: - | C7: 6 months
A10: Organizational Structure
A11: Business unit | B11: Department | C11: Target headcount | D11: % of workforce
A12: Client Operations | B12: Customer Support | C12: 700 | D12: 0.194
A13: Client Operations | B13: Implementation | C13: 450 | D13: 0.125
A14: Client Operations | B14: Service Delivery | C14: 470 | D14: 0.131
A15: Technology and Product | B15: Engineering | C15: 600 | D15: 0.167
A16: Technology and Product | B16: Data and Analytics | C16: 270 | D16: 0.075
A17: Technology and Product | B17: Product | C17: 390 | D17: 0.108
A18: Corporate Services | B18: Human Resources | C18: 180 | D18: 0.05
A19: Corporate Services | B19: Finance | C19: 180 | D19: 0.05
A20: Corporate Services | B20: Sales and Marketing | C20: 360 | D20: 0.1
A21: Total | C21: =SUBTOTAL(109,Table6[Target headcount]) -> 3600 | D21: =SUBTOTAL(109,Table6[% of workforce]) -> 1
A23: Job-level Distribution
A24: Job level | B24: Target % | C24: Approximate headcount
A25: Entry Level | B25: 0.18 | C25: 648
A26: Professional | B26: 0.4 | C26: 1440
A27: Senior Professional | B27: 0.25 | C27: 900
A28: Manager | B28: 0.12 | C28: 432
A29: Director and Above | B29: 0.05 | C29: 180
A30: Total | B30: =SUBTOTAL(109,Table8[Target %]) -> 1 | C30: =SUBTOTAL(109,Table8[Approximate headcount]) -> 3600
A32: Tenure Targets
A33: Tenure group | B33: Target % | C33: Approximate headcount
A34: Less than 1 year | B34: 0.15 | C34: 540
A35: 1–2 years | B35: 0.25 | C35: 900
A36: 3–5 years | B36: 0.3 | C36: 1080
A37: 6–10 years | B37: 0.2 | C37: 720
A38: 11 or more years | B38: 0.1 | C38: 360
A39: Total | B39: =SUBTOTAL(109,Table11[Target %]) -> 1 | C39: =SUBTOTAL(109,Table11[Approximate headcount]) -> 3600
A41: Work Arrangements
A42: Work arrangement | B42: Target % | C42: Approximate headcount
A43: On-site | B43: 0.35 | C43: 1260
A44: Hybrid | B44: 0.4 | C44: 1440
A45: Remote | B45: 0.25 | C45: 900
A46: Total | B46: =SUBTOTAL(109,Table12[Target %]) -> 1 | C46: =SUBTOTAL(109,Table12[Approximate headcount]) -> 3600
...

Sheet Change_Log
A1: Version | B1: Date | C1: Item or sheet | D1: Change | E1: Reason
A2: 0.1 | B2: 46240 | C2: Construct_Item_Map | D2: Created initial item pool | E2: Initial survey development
A3: 0.2 | B3: 46240 | C3: its_02 | D3: Revised intent-to-stay wording | E3: Removed potentially confusing frequency wording
A4: 0.3 | B4: 46240 | C4: Response_Scales | D4: Defined five-point agreement response scale | E4: Standardize survey response coding
A5: 0.4 | B5: 46243 | C5: Data_Dictionary | D5: Added survey-response variables and metadata | E5: Document survey data structure
A6: 0.5 | B6: 46243 | C6: Data_Dictionary | D6: Added employee population, organizational, tenure, eligibility, and participation variables | E6: Define fields required for population and response-rate analysis
A7: 0.6 | B7: 46243 | C7: Population_Spec | D7: Added synthetic workforce population assumptions and target distributions | E7: Define population-generation assumptions before creating synthetic data
A8: 0.7 | B8: 46243 | C8: Population_Spec | D8: Added generation dependencies, department-specific work-arrangement probabilities, and job-level mix assumptions | E8: Define relationships required for realistic synthetic population generation
